<?xml version="1.0"?>
<!-- Materials -->
<robot xmlns:xacro="http://www.ros.org/wiki/xacro" name="mp_500">
    
    <material name="Neobotix/Black">
        <color rgba="0.0 0.0 0.0 1.0"/>
    </material>

    <material name="Neobotix/Blue">
        <color rgba="0.0 0.0 0.8 1.0"/>
    </material>

    <material name="Neobotix/Green">
        <color rgba="0.0 0.8 0.0 1.0"/>
    </material>

    <material name="Neobotix/Grey">
        <color rgba="0.7 0.7 0.7 1.0"/>
    </material>

    <material name="Neobotix/Grey2">
        <color rgba="0.9 0.9 0.9 1.0"/>
    </material>

    <material name="Neobotix/Red">
        <color rgba="0.8 0.0 0.0 1.0"/>
    </material>

    <material name="Neobotix/White">
        <color rgba="1.0 1.0 1.0 1.0"/>
    </material>
    
    <material name="Neobotix/Yellow">
        <color rgba="1.0 1.0 0 10" />
    </material>

<!--++++++++++++++++++++++++++++++base_link++++++++++++++++++++++++++++++++++++++++++++++++++++--> 
<!--++++++++++++++++++++body++++++++++++++++++++++++++++--> 
  <link name="base_link">
      <!--inertial>
        <mass value="67.010" />
        <origin xyz="0.0 0.0 0.01" rpy="0 0 0"/>
        <inertia ixx="1417853.715" ixy="17813.155" ixz="-21078.206"
                 iyy="2030191.708" iyz="-4813.295" 
                 izz="2180211.662" />
      </inertial-->
	  <!--inertial>
		  <mass value="70.67" />
		    <origin xyz="0 0.10 0.244" rpy="0 0 0"/>
		    <inertia ixx="2.5" ixy="0.0" ixz="0.0"
		             iyy="1.5" iyz="0.0" 
		             izz="2.9" />
	  </inertial-->
       <inertial>
		  <mass value="5.67" />
		    <origin xyz="0.10 0 0.244" rpy="0 0 0"/>
		    <inertia ixx="0.25" ixy="0.0" ixz="0.0"
		             iyy="0.25" iyz="0.0" 
		             izz="0.25" />
	  </inertial>
      <visual name='body'>
        <!--origin xyz="0.0 0.0 0.234" rpy="0 0 1.57" /--><!-- for cylinder -->
	<origin xyz="0.0 0.0 0.09" rpy="0 0 -1.57" /><!-- for STL -->
              <geometry>
                 <mesh filename="package://neo_mp_500/robot_model/mp_500/meshes/MP500-BODY.STL" scale="0.01 0.01 0.01"/>
	    	<!--cylinder length="0.381" radius="0.2545"/-->
	    	<!--box size="0.445 0.277 0.17"/-->
              </geometry>
        <material name="Neobotix/Grey" />
       </visual>
      <collision name='body_collision'>
        <origin xyz="0.10 0 0.244" rpy="0 0 -1.57" />
        <geometry>
          <box size="0.400 0.600 0.320"/>
          <!--cylinder length="0.381" radius="0.2545"/-->
        </geometry>
      </collision>
</link>


<!--+++++++++++++++++++wheel_left_link++++++++++++++++++++++++--> 
	<link name="wheel_left_link" type="wheel">
    	  <inertial>
      		<mass value="0.15" />
     		 <origin xyz="0 0 0" rpy="0 0 0" />
      		<inertia ixx="0.0007" ixy="0" ixz="0" iyy="0.0007" iyz="0" izz="0.0007" />
    	  </inertial>

    <visual>
     	<origin xyz="0 0 0" rpy="0 0 -1.57" />
     	<geometry>
		<mesh filename="package://neo_mp_500/robot_model/mp_500/meshes/MP500-WHEEL.STL" scale="0.01 0.01 0.01" /> 
     	</geometry>
       
     	<material name="Neobotix/Black" />
    </visual>
    <collision>
     	<origin xyz="0 0 0" rpy="0 1.57 -1.57" />
     	<geometry>
        	<cylinder radius="0.125" length="0.07"/>
     	</geometry>
    </collision>
			
</link>

<!--+++++++++++++++++++wheel_left_joint++++++++++++++++++++++++--> 
	<joint name="wheel_left_joint" type="revolute">
		<origin xyz="0.005 0.255 0.13" rpy="0 0 0" />
    	<axis xyz="0 1 0"/>
    	<limit effort="1000.0" lower="-1e+16" upper="1e+16" velocity="3.5"/>
    	<joint_properties damping="0.0" friction="0.0" />
    	<parent link="base_link" />
    	<child link="wheel_left_link" />
    </joint>

<!--+++++++++++++++++++wheel_right_link++++++++++++++++++++++++--> 
<!--Mesh Volume is 3587.704102
Mesh Surface is 1876.550415
Thin shell barycenter -25.340059 -0.000027 4.499997
Center of Mass is -25.340000 -0.000164 4.500009
Inertia Tensor is :
| 322624.937500 -0.068522 -1.293689 |
| -0.068522 179104.328125 -1.342927 |
| -1.293689 -1.342927 179079.796875 |
Principal axes are :
| 1.000000 -0.000000 0.000009 |
| -0.000000 0.998514 0.054499 |
| -0.000009 -0.054499 0.998514 |
axis momenta are :
| 322624.937500 179104.406250 179079.718750 |
Mesh Volume is 0.000000
Mesh Surface is 0.000019
Thin shell barycenter -0.002534 -0.000000 0.000450
Center of Mass is -0.002534 -0.000000 0.000450
Inertia Tensor is :
| 0.000000 -0.000000 -0.000000 |
| -0.000000 0.000000 -0.000000 |
| -0.000000 -0.000000 0.000000 |
Principal axes are :
| 1.000000 -0.000000 0.000009 |
| -0.000000 0.998526 0.054276 |
| -0.000009 -0.054276 0.998526 |
axis momenta are :
| 0.000000 0.000000 0.000000 | -->
<link name="wheel_right_link" type="wheel">
	<inertial>
		  <mass value="0.15" />
		  <origin xyz="0 0 0" rpy="0 0 -1.57" />
		  <!--inertia ixx="0.0051" ixy="0" ixz="0" iyy="0.0051" iyz="0" izz="0.009" /-->
                  <inertia ixx="0.0007" ixy="0" ixz="0" iyy="0.0007" iyz="0" izz="0.0007" />
	</inertial>

		<visual>
		 	<origin xyz="0 0 0" rpy="0 0 -1.57" />
		 	<geometry>
				<mesh filename="package://neo_mp_500/robot_model/mp_500/meshes/MP500-WHEEL.STL" scale="0.01 0.01 0.01" />
		 	</geometry>
		 	<material name="Neobotix/Black" />
		</visual>

		<collision>
		 	<origin xyz="0 0 0" rpy="0 1.57 -1.57" />
		 	<geometry>
		    	<cylinder radius="0.125" length="0.07"/>
		 	</geometry>
		</collision>
	</link>

<!--+++++++++++++++++++wheel_right_joint++++++++++++++++++++++++--> 
	<joint name="wheel_right_joint" type="revolute">
    	<origin xyz="0.005 -0.255 0.13" rpy="0 0 0" />
    	<axis xyz="0 1 0"/>
    	<limit effort="1000.0" lower="-1e+16" upper="1e+16" velocity="3.5"/>
    	<joint_properties damping="0.0" friction="0.0" />
    	<parent link="base_link" />
    	<child link="wheel_right_link" />
    </joint>


<!--+++++++++++++++++++laserscanner_front_joint++++++++++++++++++++++++--> 
	<joint name="laserscanner_front_joint" type="fixed">
		  <axis xyz="0 0 1" />
		  <origin xyz="-0.234 0 0.241" rpy="0 0 0" />
		  <parent link="base_link"/>
		  <child link="laserscanner_front_link"/>
	</joint>

<!--+++++++++++++++++++laserscanner_front_link++++++++++++++++++++++++-->
	<link name="laserscanner_front_link" type="laser">
		<inertial>
			<mass value="0.01" />
			<origin xyz="0 0 -0.04" rpy="3.14 0 -1.57" />
			<inertia ixx="0.0001" ixy="0" ixz="0" iyy="0.000001" iyz="0" izz="0.0001" />
	  	</inertial>
	  	<visual>
			<origin xyz="0 0 -0.04" rpy="3.14 0 -1.57" />
			<geometry>
                             <!--cylinder length="0.154" radius="0.053" /-->		  		
                             <mesh filename="package://neo_mp_500/robot_model/mp_500/meshes/SICK-S300.STL" />
			</geometry>
			<material name="Neobotix/Yellow" />
	  	</visual>
	  	<collision>
			<origin xyz="0 0 -0.04" rpy="3.14 0 -1.57" />
			<geometry>
		  	<cylinder length="0.154" radius="0.053" />
			</geometry>
	  	</collision>
	</link>
<!--+++++++++++++++ wheel_hanger+++++++++++++++++++++++++++-->
<link name="hanger">
	<inertial>
		  <mass value="0" />
		  <origin xyz="0 0 0" rpy="0 0 0" />
		  <inertia ixx="0.0013" ixy="0" ixz="0" iyy="0.0013" iyz="0" izz="0.0013" />
	</inertial>
	<visual>
	 	<origin xyz="0 0 0" rpy="0 0 -1.57" />
	 	<geometry>
		      <mesh filename="package://neo_mp_500/robot_model/mp_500/meshes/HANGER-WHEEL.STL" scale="0.01 0.01 0.01" />
		 </geometry>
		 <material name="Neobotix/Grey" />
	</visual>
        <collision>
		 <origin xyz="0 0 0" rpy="0 0 -1.57" />
		 <geometry>
          	 <sphere radius="0.00115"/>
		 </geometry>
	</collision>
</link>

<joint name="hanger_joint" type="fixed">
    	<origin xyz="0.425 0 0.12" rpy="0 0 0"/>
    	<axis xyz="0 0 1"/>
    	<limit effort="1000.0" lower="-1e+16" upper="1e+16" velocity="13.5"/>
    	<joint_properties damping="0.0" friction="0.0" />
    	<parent link="base_link" />
    	<child link="hanger" />
    </joint>

<!--+++++++++++++++ castor_front +++++++++++++++++++++++++++-->
<link name="castor_front">
	<inertial>
		  <mass value="0.05" />
		  <origin xyz="0 0 0" rpy="0 0 0" />
		  <inertia ixx="0.0013" ixy="0" ixz="0" iyy="0.0013" iyz="0" izz="0.0013" />
	</inertial>
	<visual>
	 	<origin xyz="0 0 0" rpy="0 0 0" />
	 	<geometry>
		   <sphere radius="0.0015"/>    
		 </geometry>
		 <material name="Neobotix/Grey" />
	</visual>
        <collision>
		 <origin xyz="0 0 0" rpy="0 0 0" />
		 <geometry>
          	 <sphere radius="0.01"/>
		 </geometry>
	</collision>
</link>

<joint name="castor_front_joint" type="fixed">
    	<origin xyz="0.54 0 0.015" rpy="0 0 0"/>
    	<axis xyz="0 0 1"/>
    	<limit effort="1000.0" lower="-1e+16" upper="1e+16" velocity="13.5"/>
    	<joint_properties damping="0.0" friction="0.0" />
    	<parent link="base_link" />
    	<child link="castor_front" />
    </joint>

<!--+++++++++++++++ castor_back +++++++++++++++++++++++++++-->
<link name="castor_back">
	<inertial>
		  <mass value="0.05" />
		  <origin xyz="0 0 0" rpy="0 0 0" />
		  <inertia ixx="0.0013" ixy="0" ixz="0" iyy="0.0013" iyz="0" izz="0.0013" />
	</inertial>
	<visual>
	 	<origin xyz="0 0 0" rpy="0 0 0" />
	 	<geometry>
		   <sphere radius="0.0015"/>    
		 </geometry>
		 <material name="Neobotix/Grey" />
	</visual>
        <collision>
		 <origin xyz="0 0 0" rpy="0 0 0" />
		 <geometry>
          	 <sphere radius="0.01"/>
		 </geometry>
	</collision>
</link>

<joint name="castor_back_joint" type="fixed">
    	<origin xyz="-0.45 0 0.015" rpy="0 0 0"/>
    	<axis xyz="0 0 1"/>
    	<limit effort="1000.0" lower="-1e+16" upper="1e+16" velocity="13.5"/>
    	<joint_properties damping="0.0" friction="0.0" />
    	<parent link="base_link" />
    	<child link="castor_back" />
    </joint>

<transmission name="wheel_left">
    <type>transmission_interface/SimpleTransmission</type>
    <joint name="wheel_left_joint">
      <hardwareInterface>VelocityJointInterface</hardwareInterface>
    </joint>
    <actuator name="wheel_left_joint_motor">
      <hardwareInterface>VelocityJointInterface</hardwareInterface>
      <mechanicalReduction>1</mechanicalReduction>
    </actuator>
  </transmission>

  <transmission name="wheel_right">
    <type>transmission_interface/SimpleTransmission</type>
    <joint name="wheel_right_joint">
      <hardwareInterface>VelocityJointInterface</hardwareInterface>
    </joint>
    <actuator name="wheel_right_joint_motor">
      <hardwareInterface>VelocityJointInterface</hardwareInterface>
      <mechanicalReduction>1</mechanicalReduction>
    </actuator>
  </transmission>

    <!--gazebo>
      <plugin name="differential_drive_controller" filename="libdiffdrive_plugin.so">
        <robotNamespace>mp_500</robotNamespace>
      </plugin>
    </gazebo-->
    
</robot>
