<?xml version="1.0" ?>
<!-- =================================================================================== -->
<!-- |    This document was autogenerated by xacro from simple_robot.urdf.xacro        | -->
<!-- |    EDITING THIS FILE BY HAND IS NOT RECOMMENDED                                 | -->
<!-- =================================================================================== -->
<robot name="simple_robot" xmlns:xacro="http://www.ros.org/wiki/xacro">
  <material name="Schunk/LightGrey">
    <color rgba="0.7 0.7 0.7 1.0"/>
  </material>
  <material name="Schunk/DarkGrey">
    <color rgba="0.4 0.4 0.4 1.0"/>
  </material>
  <material name="Schunk/Black">
    <color rgba="0.0 0.0 0.0 1.0"/>
  </material>
  <material name="Schunk/DarkGolden">
    <color rgba="0.4 0.4 0.3 1.0"/>
  </material>
  <material name="Schunk/Blue">
    <color rgba="0.0 0.0 0.8 1.0"/>
  </material>
  <!-- ros_control plugin -->
  <gazebo>
    <plugin filename="libgazebo_ros_control.so" name="gazebo_ros_control">
      <robotNamespace>/simple_robot</robotNamespace>
      <!--<jointName>arm_1_joint, arm_2_joint, arm_3_joint, arm_4_joint, arm_5_joint, arm_6_joint, arm_7_joint, arm_8_joint, wheel_right_joint, wheel_left_joint</jointName>
      <robotParam>/robot_description</robotParam>-->
      <robotSimType>gazebo_ros_control/DefaultRobotHWSim</robotSimType>
    </plugin>
  </gazebo>
  <!-- Left Wheel -->
  <gazebo reference="wheel_right_link">
    <mu1>1.0</mu1>
    <mu2>1.0</mu2>
    <kp>10000000.0</kp>
    <kd>1.0</kd>
    <fdir1 value="1 0 0"/>
  </gazebo>
  <!-- Base Link -->
  <gazebo reference="mobile_base_link">
  </gazebo>
  <gazebo reference="castor_front_collision">
    <mu1>0.0</mu1>
    <mu2>0.0</mu2>
  </gazebo>
  <!-- Base Link -->
  <!--  <gazebo reference="mobile_base_link">
    <surface>
      <friction>
        <ode>
          <mu>0</mu>
          <mu2>0</mu2>
          <slip1>1.0</slip1>
          <slip2>1.0</slip2>
        </ode>
      </friction>
    </surface>
  </gazebo>-->
  <!-- Right Wheel -->
  <gazebo reference="wheel_right_link">
    <mu1>1.0</mu1>
    <mu2>1.0</mu2>
    <kp>10000000.0</kp>
    <kd>1.0</kd>
    <fdir1 value="1 0 0"/>
  </gazebo>
  <!--  <gazebo>
    <plugin name="ground_truth" filename="libgazebo_ros_p3d.so">
      <frameName>map</frameName>
      <bodyName>mobile_base_link</bodyName>
      <topicName>simple_robot/odom</topicName>
      <updateRate>30.0</updateRate>
    </plugin>
  </gazebo>-->
  <!--  <gazebo>
    <plugin name="differential_drive_controller" filename="libgazebo_ros_diff_drive.so">

      <robotNamespace>/simple_robot</robotNamespace>
    		  
      <alwaysOn>true</alwaysOn>
      <updateRate>100</updateRate>
      <leftJoint>wheel_left_joint</leftJoint>
      <rightJoint>wheel_right_joint</rightJoint>
      <wheelSeparation>0.4</wheelSeparation>
      <wheelDiameter>0.2</wheelDiameter>
      <torque>20</torque>
      <commandTopic>/simple_robot/mobile_base_controller/cmd_vel</commandTopic>
      <odometryTopic>odom</odometryTopic>
      <odometryFrame>map</odometryFrame>
      <robotBaseFrame>mobile_base_link</robotBaseFrame>
      
      <legacyMode>false</legacyMode>
      
      <rosDebugLevel>Debug</rosDebugLevel>
      <publishWheelTF>true</publishWheelTF>
      <publishWheelJointState>true</publishWheelJointState>
      <wheelAcceleration>5</wheelAcceleration>
      <wheelTorque>20</wheelTorque>
      <publishTf>1</publishTf>
      <odometrySource>encoder</odometrySource>
    </plugin>

    <plugin name="joint_state_publisher" filename="libgazebo_ros_joint_state_publisher.so">
    <jointName>wheel_left_joint, wheel_right_joint</jointName>
    </plugin>
  </gazebo>-->
  <gazebo reference="mobile_base_link">
    <gravity>true</gravity>
    <self_collide>false</self_collide>
    <material value="Gazebo/Grey"/>
  </gazebo>
  <gazebo reference="wheel_right_link">
    <gravity>true</gravity>
    <self_collide>false</self_collide>
    <material value="Gazebo/Black"/>
  </gazebo>
  <gazebo reference="wheel_left_link">
    <gravity>true</gravity>
    <self_collide>false</self_collide>
    <material value="Gazebo/Black"/>
  </gazebo>
  <gazebo reference="arm_base_link">
    <gravity>true</gravity>
    <self_collide>false</self_collide>
    <material value="Gazebo/Grey"/>
  </gazebo>
  <gazebo reference="arm_1_link">
    <gravity>true</gravity>
    <self_collide>false</self_collide>
    <material value="Gazebo/Orange"/>
  </gazebo>
  <gazebo reference="arm_2_link">
    <gravity>true</gravity>
    <self_collide>false</self_collide>
    <material value="Gazebo/Blue"/>
  </gazebo>
  <gazebo reference="arm_3_link">
    <gravity>true</gravity>
    <self_collide>false</self_collide>
    <material value="Gazebo/Orange"/>
  </gazebo>
  <gazebo reference="arm_4_link">
    <gravity>true</gravity>
    <self_collide>false</self_collide>
    <material value="Gazebo/Blue"/>
  </gazebo>
  <gazebo reference="arm_5_link">
    <gravity>true</gravity>
    <self_collide>false</self_collide>
    <material value="Gazebo/Orange"/>
  </gazebo>
  <gazebo reference="arm_6_link">
    <gravity>true</gravity>
    <self_collide>false</self_collide>
    <material value="Gazebo/Blue"/>
  </gazebo>
  <gazebo reference="arm_7_link">
    <gravity>true</gravity>
    <self_collide>false</self_collide>
    <material value="Gazebo/Orange"/>
  </gazebo>
  <gazebo reference="arm_8_link">
    <gravity>true</gravity>
    <self_collide>false</self_collide>
    <material value="Gazebo/Blue"/>
  </gazebo>
  <transmission name="wheel_right_trans">
    <type>transmission_interface/SimpleTransmission</type>
    <joint name="wheel_right_joint">
      <!--<hardwareInterface>hardware_interface/EffortJointInterface</hardwareInterface>-->
      <hardwareInterface>hardware_interface/VelocityJointInterface</hardwareInterface>
    </joint>
    <actuator name="wheel_right_motor">
      <mechanicalReduction>1</mechanicalReduction>
    </actuator>
  </transmission>
  <transmission name="wheel_left_trans">
    <type>transmission_interface/SimpleTransmission</type>
    <joint name="wheel_left_joint">
      <!--<hardwareInterface>hardware_interface/EffortJointInterface</hardwareInterface>-->
      <hardwareInterface>hardware_interface/VelocityJointInterface</hardwareInterface>
    </joint>
    <actuator name="wheel_left_motor">
      <mechanicalReduction>1</mechanicalReduction>
    </actuator>
  </transmission>
  <transmission name="arm_1_trans">
    <type>transmission_interface/SimpleTransmission</type>
    <joint name="arm_1_joint">
      <hardwareInterface>hardware_interface/PositionJointInterface</hardwareInterface>
      <!--hardwareInterface>hardware_interface/VelocityJointInterface</hardwareInterface>
      <hardwareInterface>EffortJointInterface</hardwareInterface-->
    </joint>
    <actuator name="arm_1_motor">
      <mechanicalReduction>1</mechanicalReduction>
    </actuator>
  </transmission>
  <transmission name="arm_2_trans">
    <type>transmission_interface/SimpleTransmission</type>
    <joint name="arm_2_joint">
      <hardwareInterface>hardware_interface/PositionJointInterface</hardwareInterface>
      <!--hardwareInterface>hardware_interface/VelocityJointInterface</hardwareInterface>
      <hardwareInterface>EffortJointInterface</hardwareInterface-->
    </joint>
    <actuator name="arm_2_motor">
      <mechanicalReduction>1</mechanicalReduction>
    </actuator>
  </transmission>
  <transmission name="arm_3_trans">
    <type>transmission_interface/SimpleTransmission</type>
    <joint name="arm_3_joint">
      <hardwareInterface>hardware_interface/PositionJointInterface</hardwareInterface>
      <!--hardwareInterface>hardware_interface/VelocityJointInterface</hardwareInterface>
      <hardwareInterface>EffortJointInterface</hardwareInterface-->
    </joint>
    <actuator name="arm_3_motor">
      <mechanicalReduction>1</mechanicalReduction>
    </actuator>
  </transmission>
  <transmission name="arm_4_trans">
    <type>transmission_interface/SimpleTransmission</type>
    <joint name="arm_4_joint">
      <hardwareInterface>hardware_interface/PositionJointInterface</hardwareInterface>
      <!--hardwareInterface>hardware_interface/VelocityJointInterface</hardwareInterface>
      <hardwareInterface>EffortJointInterface</hardwareInterface-->
    </joint>
    <actuator name="arm_4_motor">
      <mechanicalReduction>1</mechanicalReduction>
    </actuator>
  </transmission>
  <transmission name="arm_5_trans">
    <type>transmission_interface/SimpleTransmission</type>
    <joint name="arm_5_joint">
      <hardwareInterface>hardware_interface/PositionJointInterface</hardwareInterface>
      <!--hardwareInterface>hardware_interface/VelocityJointInterface</hardwareInterface>
      <hardwareInterface>EffortJointInterface</hardwareInterface-->
    </joint>
    <actuator name="arm_5_motor">
      <mechanicalReduction>1</mechanicalReduction>
    </actuator>
  </transmission>
  <transmission name="arm_6_trans">
    <type>transmission_interface/SimpleTransmission</type>
    <joint name="arm_6_joint">
      <hardwareInterface>hardware_interface/PositionJointInterface</hardwareInterface>
      <!--hardwareInterface>hardware_interface/VelocityJointInterface</hardwareInterface>
      <hardwareInterface>EffortJointInterface</hardwareInterface-->
    </joint>
    <actuator name="arm_6_motor">
      <mechanicalReduction>1</mechanicalReduction>
    </actuator>
  </transmission>
  <transmission name="arm_7_trans">
    <type>transmission_interface/SimpleTransmission</type>
    <joint name="arm_7_joint">
      <hardwareInterface>hardware_interface/PositionJointInterface</hardwareInterface>
      <!--hardwareInterface>hardware_interface/VelocityJointInterface</hardwareInterface>
      <hardwareInterface>EffortJointInterface</hardwareInterface-->
    </joint>
    <actuator name="arm_7_motor">
      <mechanicalReduction>1</mechanicalReduction>
    </actuator>
  </transmission>
  <transmission name="arm_8_trans">
    <type>transmission_interface/SimpleTransmission</type>
    <joint name="arm_8_joint">
      <hardwareInterface>hardware_interface/PositionJointInterface</hardwareInterface>
      <!--hardwareInterface>hardware_interface/VelocityJointInterface</hardwareInterface>
      <hardwareInterface>EffortJointInterface</hardwareInterface-->
    </joint>
    <actuator name="arm_8_motor">
      <mechanicalReduction>1</mechanicalReduction>
    </actuator>
  </transmission>
  <!--    <gazebo>
      <plugin name="ros_control" filename="libhwi_switch_gazebo_ros_control.so">
        <robotNamespace>simple_robot</robotNamespace>
        &lt;!&ndash;<filterJointsParam>joint_names</filterJointsParam>&ndash;&gt;
      </plugin>
    </gazebo>-->
  <robotBaseFrame>mobile_base_link</robotBaseFrame>
  <link name="mobile_base_link">
    <visual>
      <geometry>
        <box size="0.6 0.4 0.2"/>
      </geometry>
      <origin rpy="0 0 0" xyz="0 0 0.15"/>
      <material name="Schunk/DarkGolden"/>
    </visual>
    <collision>
      <origin rpy="0 0 0" xyz="0 0 0.15"/>
      <geometry>
        <box size="0.6 0.4 0.2"/>
      </geometry>
    </collision>
    <inertial>
      <mass value="50"/>
      <origin rpy="0 0 0" xyz="0 0 0.15"/>
      <inertia ixx="0.833333333333" ixy="0" ixz="0" iyy="1.66666666667" iyz="0" izz="1.66666666667"/>
    </inertial>
    <!--castor-->
    <visual>
      <origin rpy="0 0 0" xyz="-0.2 0 0"/>
      <geometry>
        <sphere radius="0.05"/>
      </geometry>
      <material name="Schunk/DarkGolden"/>
    </visual>
    <collision name="castor_front_collision">
      <origin rpy="0 0 0" xyz="-0.2 0 0"/>
      <geometry>
        <sphere radius="0.05"/>
      </geometry>
    </collision>
    <inertial>
      <mass value="5"/>
      <origin rpy="0 0 0" xyz="-0.2 0 0"/>
      <inertia ixx="0.005" ixy="0" ixz="0" iyy="0.005" iyz="0" izz="0.005"/>
    </inertial>
  </link>
  <link name="mobile_dummy_link">
  </link>
  <joint name="mobile_dummy_joint" type="fixed">
    <parent link="mobile_base_link"/>
    <child link="mobile_dummy_link"/>
    <origin xyz="0 0 0"/>
  </joint>
  <!--link of right wheel" /-->
  <link name="wheel_right_link">
    <visual>
      <geometry>
        <cylinder length="0.05" radius="0.1"/>
      </geometry>
      <origin rpy="0 1.57079632679 1.57079632679" xyz="0 0 0"/>
      <material name="Schunk/Black"/>
    </visual>
    <collision>
      <origin rpy="0 1.57079632679 1.57079632679" xyz="0 0 0"/>
      <geometry>
        <cylinder length="0.05" radius="0.1"/>
      </geometry>
    </collision>
    <inertial>
      <mass value="5"/>
      <origin rpy="0 1.57079632679 1.57079632679" xyz="0 0 0"/>
      <inertia ixx="0.0135416666667" ixy="0" ixz="0" iyy="0.0135416666667" iyz="0" izz="0.025"/>
    </inertial>
  </link>
  <joint name="wheel_right_joint" type="continuous">
    <parent link="mobile_base_link"/>
    <child link="wheel_right_link"/>
    <origin xyz="0.2 0.225 0.05"/>
    <axis xyz="0 1 0"/>
    <limit effort="100.0" velocity="100"/>
    <dynamics damping="0.0" friction="0.0"/>
  </joint>
  <!--link of left wheel" /-->
  <link name="wheel_left_link">
    <visual>
      <geometry>
        <cylinder length="0.05" radius="0.1"/>
      </geometry>
      <origin rpy="0 1.57079632679 1.57079632679" xyz="0 0 0"/>
      <material name="Schunk/Black"/>
    </visual>
    <collision>
      <origin rpy="0 1.57079632679 1.57079632679" xyz="0 0 0"/>
      <geometry>
        <cylinder length="0.05" radius="0.1"/>
      </geometry>
    </collision>
    <inertial>
      <mass value="5"/>
      <origin rpy="0 1.57079632679 1.57079632679" xyz="0 0 0"/>
      <inertia ixx="0.0135416666667" ixy="0" ixz="0" iyy="0.0135416666667" iyz="0" izz="0.025"/>
    </inertial>
  </link>
  <joint name="wheel_left_joint" type="continuous">
    <parent link="mobile_base_link"/>
    <child link="wheel_left_link"/>
    <origin xyz="0.2 -0.225 0.05"/>
    <axis xyz="0 1 0"/>
    <limit effort="100.0" velocity="100"/>
    <dynamics damping="0.0" friction="0.0"/>
  </joint>
  <!--link of front wheel" />
  <link name="mobile_vor_wheel">
    <visual>
      <geometry>
        <sphere radius="0.1"/>
      </geometry>
      <origin rpy="0 0 0" xyz="0 0 0"/>
      <material name="Schunk/DarkGrey"/>
    </visual>
    <collision>
      <geometry>
        <sphere radius="0.1"/>
      </geometry>
    </collision>
  </link>

  <joint name="base_to_vor_wheel" type="continuous">
    <parent link="mobile_base_link"/>
    <child link="mobile_vor_wheel"/>
    <origin xyz="-0.2 0 0.05"/>
  </joint-->
  <link name="arm_base_link">
    <visual>
      <geometry>
        <cylinder length="0.05" radius="0.1"/>
      </geometry>
      <origin rpy="0 0 0" xyz="0 0 0"/>
      <material name="Schunk/DarkGolden"/>
    </visual>
    <collision>
      <geometry>
        <cylinder length="0.05" radius="0.1"/>
      </geometry>
    </collision>
    <inertial>
      <mass value="0.01"/>
      <origin rpy="0 0 0" xyz="0 0 0"/>
      <inertia ixx="0.001" ixy="0.0" ixz="0.0" iyy="0.001" iyz="0.0" izz="0.001"/>
    </inertial>
    <!--<inertial>
      <mass value="0.01"/>
      <origin rpy="0 0 0" xyz="0 0 0"/>
      <inertia ixx="0.001" ixy="0.0" ixz="0.0" iyy="0.001" iyz="0.0" izz="0.001"/>
    </inertial>-->
  </link>
  <!-- joint between base_link and lwa4p_extended_connector_link -->
  <joint name="arm_base_joint" type="fixed">
    <origin rpy="0 0 0" xyz="-0.1 0 0.275"/>
    <parent link="mobile_base_link"/>
    <child link="arm_base_link"/>
  </joint>
  <!-- link 1 -->
  <link name="arm_1_link">
    <visual>
      <geometry>
        <box size="0.04 0.04 0.04"/>
      </geometry>
      <origin rpy="0 0 0" xyz="0 0 0"/>
      <material name="Schunk/DarkGrey"/>
    </visual>
    <collision>
      <geometry>
        <box size="0.04 0.04 0.04"/>
      </geometry>
    </collision>
    <inertial>
      <mass value="0.01"/>
      <origin rpy="0 0 0" xyz="0 0 0"/>
      <inertia ixx="0.001" ixy="0.0" ixz="0.0" iyy="0.001" iyz="0.0" izz="0.001"/>
    </inertial>
    <!--<inertial>
      <mass value="0.01"/>
      <origin rpy="0 0 0" xyz="0 0 0"/>
      <inertia ixx="0.001" ixy="0.0" ixz="0.0" iyy="0.001" iyz="0.0" izz="0.001"/>
    </inertial>-->
  </link>
  <!-- joint 1 between base_link and arm_1_link -->
  <joint name="arm_1_joint" type="revolute">
    <origin rpy="0 0 0" xyz="0 0 0.045"/>
    <parent link="arm_base_link"/>
    <child link="arm_1_link"/>
    <axis xyz="0 0 1"/>
    <limit effort="370" lower="-3.14" upper="3.14" velocity="1.26"/>
  </joint>
  <!-- link 2 -->
  <link name="arm_2_link">
    <visual>
      <geometry>
        <cylinder length="0.04" radius="0.02"/>
      </geometry>
      <origin rpy="1.57079632679 0 0" xyz="0 0 0"/>
      <material name="Schunk/Blue"/>
    </visual>
    <collision>
      <origin rpy="1.57079632679 0 0" xyz="0 0 0"/>
      <geometry>
        <cylinder length="0.04" radius="0.02"/>
      </geometry>
    </collision>
    <!--<xacro:default_inertial/>-->
    <inertial>
      <mass value="0.01"/>
      <origin rpy="1.57079632679 0 0" xyz="0 0 0"/>
      <inertia ixx="0.001" ixy="0.0" ixz="0.0" iyy="0.001" iyz="0.0" izz="0.001"/>
    </inertial>
    <visual>
      <origin rpy="0 0 0" xyz="0 0 0.32"/>
      <geometry>
        <box size="0.04 0.04 0.6"/>
      </geometry>
      <material name="Schunk/Blue"/>
    </visual>
    <collision>
      <origin rpy="0 0 0" xyz="0 0 0.32"/>
      <geometry>
        <box size="0.04 0.04 0.6"/>
      </geometry>
    </collision>
    <!--<xacro:default_inertial/>-->
    <inertial>
      <mass value="0.01"/>
      <origin rpy="0 0 0" xyz="0 0 0.32"/>
      <inertia ixx="0.001" ixy="0.0" ixz="0.0" iyy="0.001" iyz="0.0" izz="0.001"/>
    </inertial>
    <visual>
      <geometry>
        <cylinder length="0.04" radius="0.02"/>
      </geometry>
      <origin rpy="1.57079632679 0 0" xyz="0 0 0.64"/>
      <material name="Schunk/Blue"/>
    </visual>
    <collision>
      <origin rpy="1.57079632679 0 0" xyz="0 0 0.64"/>
      <geometry>
        <cylinder length="0.04" radius="0.02"/>
      </geometry>
    </collision>
    <!--<xacro:default_inertial/>-->
    <inertial>
      <mass value="0.01"/>
      <origin rpy="0 1.57079632679 0" xyz="0 0 0.64"/>
      <inertia ixx="0.001" ixy="0.0" ixz="0.0" iyy="0.001" iyz="0.0" izz="0.001"/>
    </inertial>
  </link>
  <!-- joint 2 between arm_1_link and arm_2_link-->
  <joint name="arm_2_joint" type="revolute">
    <origin rpy="0 0 0" xyz="0 -0.04 0"/>
    <parent link="arm_1_link"/>
    <child link="arm_2_link"/>
    <axis xyz="0 1 0"/>
    <limit effort="370" lower="-1.57" upper="1.57" velocity="1.26"/>
    <safety_controller k_position="20" k_velocity="50" soft_lower_limit="-6.27" soft_upper_limit="6.27"/>
  </joint>
  <!-- link 3 -->
  <link name="arm_3_link">
    <visual>
      <geometry>
        <box size="0.04 0.04 0.04"/>
      </geometry>
      <origin rpy="0 0 0" xyz="0 0 0"/>
      <material name="Schunk/DarkGrey"/>
    </visual>
    <collision>
      <geometry>
        <box size="0.04 0.04 0.04"/>
      </geometry>
    </collision>
    <inertial>
      <mass value="0.01"/>
      <origin rpy="0 0 0" xyz="0 0 0"/>
      <inertia ixx="0.001" ixy="0.0" ixz="0.0" iyy="0.001" iyz="0.0" izz="0.001"/>
    </inertial>
    <!--<inertial>
      <mass value="0.01"/>
      <origin rpy="0 0 0" xyz="0 0 0"/>
      <inertia ixx="0.001" ixy="0.0" ixz="0.0" iyy="0.001" iyz="0.0" izz="0.001"/>
    </inertial>-->
  </link>
  <!-- joint 3 between link 2 and link3 -->
  <joint name="arm_3_joint" type="revolute">
    <origin rpy="0 0 0" xyz="0 0.04 0.64"/>
    <parent link="arm_2_link"/>
    <child link="arm_3_link"/>
    <axis xyz="0 1 0"/>
    <limit effort="370" lower="-2.65" upper="2.65" velocity="1.26"/>
    <safety_controller k_position="20" k_velocity="50" soft_lower_limit="-6.27" soft_upper_limit="6.27"/>
  </joint>
  <!-- link 4 -->
  <link name="arm_4_link">
    <visual>
      <geometry>
        <cylinder length="0.04" radius="0.02"/>
      </geometry>
      <origin rpy="0 1.57079632679 0" xyz="0 0 0"/>
      <material name="Schunk/Blue"/>
    </visual>
    <collision>
      <geometry>
        <cylinder length="0.04" radius="0.02"/>
      </geometry>
    </collision>
    <inertial>
      <mass value="0.01"/>
      <origin rpy="0 0 0" xyz="0 0 0"/>
      <inertia ixx="0.001" ixy="0.0" ixz="0.0" iyy="0.001" iyz="0.0" izz="0.001"/>
    </inertial>
    <!--<inertial>
      <mass value="0.01"/>
      <origin rpy="0 ${PI/2} 0" xyz="0 0 0"/>
      <inertia ixx="0.001" ixy="0.0" ixz="0.0" iyy="0.001" iyz="0.0" izz="0.001"/>
    </inertial>-->
    <visual>
      <origin rpy="0 0 0" xyz="0 0 0.22"/>
      <geometry>
        <box size="0.04 0.04 0.4"/>
      </geometry>
      <material name="Schunk/Blue"/>
    </visual>
    <collision>
      <origin rpy="0 0 0" xyz="0 0 0.22"/>
      <geometry>
        <box size="0.04 0.04 0.4"/>
      </geometry>
    </collision>
    <!--<xacro:default_inertial/>-->
    <inertial>
      <mass value="0.01"/>
      <origin rpy="0 0 0" xyz="0 0 0.22"/>
      <inertia ixx="0.001" ixy="0.0" ixz="0.0" iyy="0.001" iyz="0.0" izz="0.001"/>
    </inertial>
    <visual>
      <geometry>
        <cylinder length="0.04" radius="0.02"/>
      </geometry>
      <origin rpy="0 1.57079632679 0" xyz="0 0 0.44"/>
      <material name="Schunk/Blue"/>
    </visual>
    <collision>
      <origin rpy="0 1.57079632679 0" xyz="0 0 0.44"/>
      <geometry>
        <cylinder length="0.04" radius="0.02"/>
      </geometry>
    </collision>
    <!--<xacro:default_inertial/>-->
    <inertial>
      <mass value="0.01"/>
      <origin rpy="0 1.57079632679 0" xyz="0 0 0.44"/>
      <inertia ixx="0.001" ixy="0.0" ixz="0.0" iyy="0.001" iyz="0.0" izz="0.001"/>
    </inertial>
  </link>
  <!-- joint 4 between arm_3_link and arm_4_link-->
  <joint name="arm_4_joint" type="revolute">
    <origin rpy="0 0 0" xyz="0.04 0.0 0.0"/>
    <parent link="arm_3_link"/>
    <child link="arm_4_link"/>
    <axis xyz="1 0 0"/>
    <limit effort="370" lower="-2.65" upper="2.65" velocity="1.26"/>
    <safety_controller k_position="20" k_velocity="50" soft_lower_limit="-6.27" soft_upper_limit="6.27"/>
  </joint>
  <!-- link 5 -->
  <link name="arm_5_link">
    <visual>
      <geometry>
        <box size="0.04 0.04 0.04"/>
      </geometry>
      <origin rpy="0 0 0" xyz="0 0 0"/>
      <material name="Schunk/DarkGrey"/>
    </visual>
    <collision>
      <geometry>
        <box size="0.04 0.04 0.04"/>
      </geometry>
    </collision>
    <inertial>
      <mass value="0.01"/>
      <origin rpy="0 0 0" xyz="0 0 0"/>
      <inertia ixx="0.001" ixy="0.0" ixz="0.0" iyy="0.001" iyz="0.0" izz="0.001"/>
    </inertial>
    <!--<inertial>
      <mass value="0.01"/>
      <origin rpy="0 0 0" xyz="0 0 0"/>
      <inertia ixx="0.001" ixy="0.0" ixz="0.0" iyy="0.001" iyz="0.0" izz="0.001"/>
    </inertial>-->
  </link>
  <!-- joint 5 between link 3 and link4 -->
  <joint name="arm_5_joint" type="revolute">
    <origin rpy="0 0 0" xyz="-0.04 0 0.44"/>
    <parent link="arm_4_link"/>
    <child link="arm_5_link"/>
    <axis xyz="1 0 0"/>
    <limit effort="370" lower="-3.14" upper="3.14" velocity="1.26"/>
    <safety_controller k_position="20" k_velocity="50" soft_lower_limit="-6.27" soft_upper_limit="6.27"/>
  </joint>
  <!-- link 6 -->
  <link name="arm_6_link">
    <visual>
      <geometry>
        <cylinder length="0.04" radius="0.02"/>
      </geometry>
      <origin rpy="1.57079632679 0 0" xyz="0 0 0"/>
      <material name="Schunk/Blue"/>
    </visual>
    <collision>
      <geometry>
        <cylinder length="0.04" radius="0.02"/>
      </geometry>
    </collision>
    <inertial>
      <mass value="0.01"/>
      <origin rpy="0 0 0" xyz="0 0 0"/>
      <inertia ixx="0.001" ixy="0.0" ixz="0.0" iyy="0.001" iyz="0.0" izz="0.001"/>
    </inertial>
    <!--<inertial>
      <mass value="0.01"/>
      <origin rpy="${PI/2} 0 0" xyz="0 0 0"/>
      <inertia ixx="0.001" ixy="0.0" ixz="0.0" iyy="0.001" iyz="0.0" izz="0.001"/>
    </inertial>-->
    <visual>
      <origin rpy="0 0 0" xyz="0 0 0.12"/>
      <geometry>
        <box size="0.04 0.04 0.2"/>
      </geometry>
      <material name="Schunk/Blue"/>
    </visual>
    <collision>
      <origin rpy="0 0 0" xyz="0 0 0.12"/>
      <geometry>
        <box size="0.04 0.04 0.2"/>
      </geometry>
    </collision>
    <!--<xacro:default_inertial/>-->
    <inertial>
      <mass value="0.01"/>
      <origin rpy="0 0 0" xyz="0 0 0.12"/>
      <inertia ixx="0.001" ixy="0.0" ixz="0.0" iyy="0.001" iyz="0.0" izz="0.001"/>
    </inertial>
    <visual>
      <geometry>
        <cylinder length="0.04" radius="0.02"/>
      </geometry>
      <origin rpy="1.57079632679 0 0" xyz="0 0 0.24"/>
      <material name="Schunk/Blue"/>
    </visual>
    <collision>
      <origin rpy="1.57079632679 0 0" xyz="0 0 0.24"/>
      <geometry>
        <cylinder length="0.04" radius="0.02"/>
      </geometry>
    </collision>
    <!--<xacro:default_inertial/>-->
    <inertial>
      <mass value="0.01"/>
      <origin rpy="1.57079632679 0 0" xyz="0 0 0.24"/>
      <inertia ixx="0.001" ixy="0.0" ixz="0.0" iyy="0.001" iyz="0.0" izz="0.001"/>
    </inertial>
  </link>
  <!-- joint 6 between arm_5_link and arm_6_link-->
  <joint name="arm_6_joint" type="revolute">
    <origin rpy="0 0 0" xyz="0 -0.04 0.0"/>
    <parent link="arm_5_link"/>
    <child link="arm_6_link"/>
    <axis xyz="0 1 0"/>
    <limit effort="370" lower="-3.14" upper="3.14" velocity="1.26"/>
    <safety_controller k_position="20" k_velocity="50" soft_lower_limit="-6.27" soft_upper_limit="6.27"/>
  </joint>
  <!-- link 7 -->
  <link name="arm_7_link">
    <visual>
      <geometry>
        <box size="0.04 0.04 0.04"/>
      </geometry>
      <origin rpy="0 0 0" xyz="0 0 0"/>
      <material name="Schunk/DarkGrey"/>
    </visual>
    <collision>
      <geometry>
        <box size="0.04 0.04 0.04"/>
      </geometry>
    </collision>
    <inertial>
      <mass value="0.01"/>
      <origin rpy="0 0 0" xyz="0 0 0"/>
      <inertia ixx="0.001" ixy="0.0" ixz="0.0" iyy="0.001" iyz="0.0" izz="0.001"/>
    </inertial>
    <!--<inertial>
      <mass value="0.01"/>
      <origin rpy="0 0 0" xyz="0 0 0"/>
      <inertia ixx="0.001" ixy="0.0" ixz="0.0" iyy="0.001" iyz="0.0" izz="0.001"/>
    </inertial>-->
  </link>
  <!-- joint 7 between link 3 and link4 -->
  <joint name="arm_7_joint" type="revolute">
    <origin rpy="0 0 0" xyz="0 0.04 0.24"/>
    <parent link="arm_6_link"/>
    <child link="arm_7_link"/>
    <axis xyz="0 1 0"/>
    <limit effort="370" lower="-3.14" upper="3.14" velocity="1.26"/>
    <safety_controller k_position="20" k_velocity="50" soft_lower_limit="-6.27" soft_upper_limit="6.27"/>
  </joint>
  <!-- link 8 ee -->
  <link name="arm_8_link">
    <visual>
      <geometry>
        <cylinder length="0.06" radius="0.02"/>
      </geometry>
      <origin rpy="0 0 0" xyz="0 0 0"/>
      <material name="Schunk/Blue"/>
    </visual>
    <collision>
      <geometry>
        <cylinder length="0.04" radius="0.02"/>
      </geometry>
    </collision>
    <inertial>
      <mass value="0.01"/>
      <origin rpy="0 0 0" xyz="0 0 0"/>
      <inertia ixx="0.001" ixy="0.0" ixz="0.0" iyy="0.001" iyz="0.0" izz="0.001"/>
    </inertial>
    <!--<inertial>
      <mass value="0.01"/>
      <origin rpy="0 0 0" xyz="0 0 0"/>
      <inertia ixx="0.001" ixy="0.0" ixz="0.0" iyy="0.001" iyz="0.0" izz="0.001"/>
    </inertial>-->
  </link>
  <!-- joint 8 ee between arm_7_link and arm_8_link-->
  <joint name="arm_8_joint" type="revolute">
    <origin rpy="0 0 0" xyz="0 0.0 0.04"/>
    <parent link="arm_7_link"/>
    <child link="arm_8_link"/>
    <axis xyz="0 0 1"/>
    <limit effort="370" lower="-0.7" upper="0.7" velocity="1.26"/>
    <safety_controller k_position="20" k_velocity="50" soft_lower_limit="-6.27" soft_upper_limit="6.27"/>
  </joint>
</robot>

